Workbook

Sheet FAQ по заполнению
A1: FAQ по заполнению вкладки «Реализованные билеты»
A2: 1. Какие данные нужно заполнять? По каждому матчу необходимо указать: • Дату игры • Количество реализованных платных и бесплатных билетов • Количество действующих платных и бесплатных абонементов/пакетов • Количество реализованных платных и бесплатных билетов в бизнес-клубах и ресторанах • Количество реализованных платных и бесплатных билетов в ложах - в случае реализации лож на весь сезон, сезонная стоимость ложи делится на количество матчей
A3: 2. Что входит в итоговую строку "Реализовано билетов, всего"? Общее количество всех реализованных билетов на соответствующий матч (сумма колонок C-J): • Платные и бесплатные билеты • Абонементы и пакеты • Билеты в бизнес-клубы и ложи
A4: 3. Что такое "бизнес-клубы и рестораны"? Это специальные места, которые обычно реализуются вместе с услугой кейтеринга (без учета лож). Если такие билеты не реализовываются, то укажите 0.
A5: 4. Что писать в колонке "Комментарий"? Любые необходимые пояснения по конкретному матчу (например, возможные ограничения по количеству зрителей, пояснения касательно билетной программы матча и т.п.).
A7: FAQ по заполнению вкладки «Доход от реализации билетов»
A8: 1. Какие данные нужно заполнять? По каждому матчу указываются: • Общая сумма дохода от реализации • Сумма дохода от реализации платных билетов • Сумма дохода от реализации абонементов/пакетов • Сумма дохода от реализации мест в бизнес-клубах и ресторанах (без учета стоимости кейтеринга) • Сумма дохода от реализации мест в ложах (без учета стоимости кейтеринга)
A9: 2. Что такое бизнес-клубы и рестораны? Это специальные зоны на арене с повышенным уровнем комфорта и доступом к кейтерингу. В отчёте указывается только доход от продажи мест, без учёта стоимости питания. Если такие билеты не реализовываются, то укажите 0.
A10: 3. Как указывать доход от абонементов/пакетов, лож, реализованных на весь сезон или его часть? Необходимо разделить общую сумму дохода от реализации на количество матчей и указать долю, приходящуюся на конкретный матч.
A11: 4. Учитывать ли стоимость кейтеринга в доходах от бизнес-клубов и лож? Нет. В отчёте указывается только стоимость мест, без учёта расходов на питание и обслуживание.
A12: 5. Что писать в комментариях? Любые пояснения
A14: FAQ по заполнению вкладки «Агенты и онлайн продажи»
... A19: 5. Что писать в комментариях? Любые пояснения

Sheet Реализованные билеты
A1: Поматчевая реализация
A2: № игры | B2: Дата | C2: Реализовано платных билетов на матч, шт. | D2: Реализовано бесплатных билетов на матч, шт. | E2: Действующие на матч платные абонементы/ пакеты, шт. | F2: Действующие на матч бесплатные абонементы/ пакеты, шт. | G2: Реализовано платных билетов в бизнес-клубы и рестораны на матч, шт. * | H2: Реализовано бесплатных билетов в бизнес-клубы и рестораны на матч, шт. * | I2: Реализоавано платных мест в ложах, шт. | J2: Реализоавано бесплатных мест в ложах, шт. | K2: Реализовано билетов на матч, всего, шт. | L2: Комментарий
A4: РЕГУЛЯРНЫЙ ЧЕМПИОНАТ
A5: 1 | B5: 45910 | C5: 5439 | D5: 289 | E5: 2444 | F5: 188 | G5: 0 | H5: 63 | I5: 316 | J5: 60 | K5: =SUM(C5:J5)
A6: 2 | B6: 45914 | C6: 5449 | D6: 329 | E6: 2453 | F6: 188 | G6: 10 | H6: 63 | I6: 316 | J6: 60 | K6: =SUM(C6:J6)
A7: 3 | B7: 45917 | C7: 3851 | D7: 1126 | E7: 2458 | F7: 188 | G7: 0 | H7: 63 | I7: 316 | J7: 60 | K7: =SUM(C7:J7)
A8: 4 | B8: 45919 | C8: 5441 | D8: 323 | E8: 2463 | F8: 188 | G8: 0 | H8: 63 | I8: 316 | J8: 60 | K8: =SUM(C8:J8)
A9: 5 | B9: 45921 | C9: 5362 | D9: 370 | E9: 2463 | F9: 188 | G9: 10 | H9: 63 | I9: 316 | J9: 60 | K9: =SUM(C9:J9)
A10: 6 | B10: 45933 | C10: 4164 | D10: 1181 | E10: 2466 | F10: 188 | G10: 10 | H10: 63 | I10: 316 | J10: 60 | K10: =SUM(C10:J10)
A11: 7 | B11: 45935 | C11: 4207 | D11: 1174 | E11: 2466 | F11: 188 | G11: 0 | H11: 63 | I11: 316 | J11: 60 | K11: =SUM(C11:J11)
A12: 8 | B12: 45937 | C12: 3572 | D12: 1818 | E12: 2466 | F12: 188 | G12: 0 | H12: 63 | I12: 316 | J12: 60 | K12: =SUM(C12:J12)
A13: 9 | B13: 45952 | C13: 5419 | D13: 325 | E13: 2466 | F13: 188 | G13: 10 | H13: 63 | I13: 316 | J13: 60 | K13: =SUM(C13:J13)
A14: 10 | B14: 45955 | C14: 5395 | D14: 384 | E14: 2470 | F14: 188 | G14: 0 | H14: 63 | I14: 316 | J14: 60 | K14: =SUM(C14:J14)
A15: 11 | B15: 45957 | C15: 5168 | D15: 595 | E15: 2470 | F15: 188 | G15: 10 | H15: 63 | I15: 316 | J15: 60 | K15: =SUM(C15:J15)
A16: 12 | B16: 45959 | C16: 5424 | D16: 346 | E16: 2470 | F16: 188 | G16: 0 | H16: 63 | I16: 316 | J16: 60 | K16: =SUM(C16:J16)
... A38: 34 | B38: 46094 | C38: 5482 | D38: 354 | E38: 2443 | F38: 188 | G38: 0 | H38: 63 | I38: 316 | J38: 60 | K38: =SUM(C38:J38)
A39: ПЛЕЙ-ОФФ
A40: 35 | B40: 46104 | C40: 5608 | D40: 290 | E40: 2163 | F40: 188 | G40: 0 | H40: 63 | I40: 316 | J40: 60 | K40: =SUM(C40:J40)
A41: 36 | B41: 46106 | C41: 5690 | D41: 363 | E41: 2163 | F41: 188 | G41: 0 | H41: 63 | I41: 316 | J41: 60 | K41: =SUM(C41:J41)
A42: 37 | B42: 46112 | C42: 5659 | D42: 387 | E42: 2163 | F42: 188 | G42: 0 | H42: 63 | I42: 316 | J42: 60 | K42: =SUM(C42:J42)
A43: 38 | B43: 46125 | C43: 5674 | D43: 371 | E43: 2163 | F43: 188 | G43: 0 | H43: 63 | I43: 316 | J43: 60 | K43: =SUM(C43:J43)
A44: 39 | B44: 46127 | C44: 5685 | D44: 387 | E44: 2163 | F44: 188 | G44: 10 | H44: 63 | I44: 316 | J44: 60 | K44: =SUM(C44:J44)
A45: 40 | B45: 46141 | C45: 5668 | D45: 367 | E45: 2163 | F45: 188 | G45: 10 | H45: 63 | I45: 316 | J45: 60 | K45: =SUM(C45:J45)
A46: 41 | B46: 46143 | C46: 5677 | D46: 388 | E46: 2163 | F46: 188 | G46: 0 | H46: 63 | I46: 316 | J46: 60 | K46: =SUM(C46:J46)
A47: 42 | B47: 46157 | C47: 5649 | D47: 396 | E47: 2163 | F47: 188 | G47: 10 | H47: 63 | I47: 316 | J47: 60 | K47: =SUM(C47:J47)
A48: 43 | B48: 46159 | C48: 5674 | D48: 383 | E48: 2163 | F48: 188 | G48: 10 | H48: 63 | I48: 316 | J48: 60 | K48: =SUM(C48:J48)
A49: 44 | B49: 46163 | C49: 5624 | D49: 365 | E49: 2163 | F49: 188 | G49: 10 | H49: 63 | I49: 316 | J49: 60 | K49: =SUM(C49:J49)
A51: * Места, в стоимость которых включен кейтеринг

Sheet Доход от реализации билетов
A1: Поматчевая реализация
A2: № игры | B2: Дата | C2: Сумма дохода от всех реализованных билетов на матч | D2: Сумма дохода от реализованных платных билетов на матч | E2: Сумма дохода от реализованных на матч платных абонементов/ пакетов, шт. * | F2: Общая сумма дохода от реализованных платных билетов в бизнес-клубы и рестораны** на матч, шт. | G2: Общая сумма дохода от реализованных платных мест в ложах *** | H2: Комментарий
A3: РЕГУЛЯРНЫЙ ЧЕМПИОНАТ
A4: 1 | B4: 45910 | C4: =SUM(D4:G4) | D4: 6189166.5 | E4: 1792583.5 | F4: 0 | G4: 1159137
A5: 2 | B5: 45914 | C5: =SUM(D5:G5) | D5: 5904206.5 | E5: 1792583.5 | F5: 65000 | G5: 1159137
A6: 3 | B6: 45917 | C6: =SUM(D6:G6) | D6: 3248436.5 | E6: 1792583.5 | F6: 0 | G6: 1159137
A7: 4 | B7: 45919 | C7: =SUM(D7:G7) | D7: 7884016.5 | E7: 1792583.5 | F7: 0 | G7: 1159137
A8: 5 | B8: 45921 | C8: =SUM(D8:G8) | D8: 8052036.5 | E8: 1792583.5 | F8: 75000 | G8: 1159137
A9: 6 | B9: 45933 | C9: =SUM(D9:G9) | D9: 3520541.5 | E9: 1792583.5 | F9: 35000 | G9: 1159137
A10: 7 | B10: 45935 | C10: =SUM(D10:G10) | D10: 4429151.5 | E10: 1792583.5 | F10: 0 | G10: 1159137
A11: 8 | B11: 45937 | C11: =SUM(D11:G11) | D11: 3110651.4 | E11: 1792583.5 | F11: 0 | G11: 1159137
A12: 9 | B12: 45952 | C12: =SUM(D12:G12) | D12: 7399235 | E12: 1792583.5 | F12: 75000 | G12: 1159137
A13: 10 | B13: 45955 | C13: =SUM(D13:G13) | D13: 5696910 | E13: 1792583.5 | F13: 0 | G13: 1159137
A14: 11 | B14: 45957 | C14: =SUM(D14:G14) | D14: 4044925 | E14: 1792583.5 | F14: 35000 | G14: 1159137
A15: 12 | B15: 45959 | C15: =SUM(D15:G15) | D15: 5861535 | E15: 1792583.5 | F15: 0 | G15: 1159137
... A37: 34 | B37: 46094 | C37: =SUM(D37:G37) | D37: 4544110 | E37: 1792583.5 | F37: 0 | G37: 1159137
A38: ПЛЕЙ-ОФФ
A39: 35 | B39: 46104 | C39: =SUM(D39:G39) | D39: 9632575 | E39: 1792583.5 | F39: 0 | G39: 1159137
A40: 36 | B40: 46106 | C40: =SUM(D40:G40) | D40: 9978330 | E40: 1792583.5 | F40: 0 | G40: 1159137
A41: 37 | B41: 46112 | C41: =SUM(D41:G41) | D41: 10893165 | E41: 1792583.5 | F41: 0 | G41: 1159137
A42: 38 | B42: 46125 | C42: =SUM(D42:G42) | D42: 13514465 | E42: 1792583.5 | F42: 0 | G42: 1159137
A43: 39 | B43: 46127 | C43: =SUM(D43:G43) | D43: 13547040 | E43: 1792583.5 | F43: 85000 | G43: 1159137
A44: 40 | B44: 46141 | C44: =SUM(D44:G44) | D44: 16726255 | E44: 1792583.5 | F44: 120000 | G44: 1159137
A45: 41 | B45: 46143 | C45: =SUM(D45:G45) | D45: 16766640 | E45: 1792583.5 | F45: 0 | G45: 1159137
A46: 42 | B46: 46157 | C46: =SUM(D46:G46) | D46: 26352570 | E46: 1792583.5 | F46: 160000 | G46: 1159137
A47: 43 | B47: 46159 | C47: =SUM(D47:G47) | D47: 26441180 | E47: 1792583.5 | F47: 160000 | G47: 1159137
A48: 44 | B48: 46163 | C48: =SUM(D48:G48) | D48: 36922350 | E48: 1792583.5 | F48: 200000 | G48: 1159137
A50: * Если абонементы продавались на сезон или несколько матчей, то необходимо разделить полученный доход на количество игр и указать результат в поматчевой разбивке
A51: ** Места, в стоимость которых включен кейтеринг. Указывается только стоимость места без стоимости кейтеринга
A52: *** Если ложи реализовывались на весь сезон или несколько матчей, то необходимо разделить полученный доход на количество игр и указать результат в поматчевой разбивке. Указывается только стоимость мест в ложе без стооимсти кейтеринга

Sheet Агенты и онлайн продажи
A1: Реализация билетов через агентов *
A2: Название агента | B2: Реализовано билетов на матчи, всего, шт. | C2: Доход клуба от реализации платных билетов на матч, руб. | D2: Размер агентской комиссии, %
A4: - | B4: - | C4: - | D4: -
A8: Реализация билетов через каналы продаж *
A9: Канал продаж | B9: Реализовано билетов на матчи, всего, шт. | C9: Доход от реализации платных билетов на матч, руб.
A10: Онлайн | B10: 198531 | C10: 328213390
A11: Оффлайн | B11: 35703 | C11: 50932302
A12: Через агентов онлайн | B12: - | C12: -
A13: Через агентов оффлайн | B13: - | C13: -
A15: * Необходимо указать данные за весь сезон (включая плей-офф)

Sheet Расчеты
B1: Расчёт метрик билетной программы — сезон 2025/2026
G2: Вместимость арены, чел.: | H2: 8965
B3: 1. Реализация билетов, шт.
B4: Показатель | C4: Значение | D4: Ед. | E4: Формула / комментарий
B5: Посещаемость за сезон (всего проходов) | C5: =(SUM('Реализованные билеты'!K5:K38)+SUM('Реализованные билеты'!K40:K49)) | D5: чел. | E5: гр. K — сумма разовых, абонементов, лож
B6: регулярный чемпионат | C6: =SUM('Реализованные билеты'!K5:K38) | D6: чел.
B7: плей-офф | C7: =SUM('Реализованные билеты'!K40:K49) | D7: чел.
B8: Платные билеты на матч (разовые) | C8: =(SUM('Реализованные билеты'!C5:C38)+SUM('Реализованные билеты'!C40:C49)) | D8: шт. | E8: гр. C
B9: Бесплатные билеты на матч (разовые) | C9: =(SUM('Реализованные билеты'!D5:D38)+SUM('Реализованные билеты'!D40:D49)) | D9: шт. | E9: гр. D
B10: Платных абонементов/пакетов (продано) | C10: =MAX(MAX('Реализованные билеты'!E5:E38),MAX('Реализованные билеты'!E40:E49)) | D10: шт. | E10: MAX действующих, гр. E
B11: Бесплатных абонементов/пакетов (продано) | C11: =MAX(MAX('Реализованные билеты'!F5:F38),MAX('Реализованные билеты'!F40:F49)) | D11: шт. | E11: MAX по гр. F
B12: абонемент-посещения за сезон (справочно) | C12: =(SUM('Реализованные билеты'!E5:E38)+SUM('Реализованные билеты'!E40:E49))+(SUM('Реализованные билеты'!F5:F38)+SUM('Реализованные билеты'!F40:F49)) | D12: чел.
B13: Платные билеты в бизнес-клубы/рестораны | C13: =(SUM('Реализованные билеты'!G5:G38)+SUM('Реализованные билеты'!G40:G49)) | D13: шт. | E13: гр. G
B14: Бесплатные билеты в бизнес-клубы/рестораны | C14: =(SUM('Реализованные билеты'!H5:H38)+SUM('Реализованные билеты'!H40:H49)) | D14: шт. | E14: гр. H
B15: Платные места в ложах | C15: =(SUM('Реализованные билеты'!I5:I38)+SUM('Реализованные билеты'!I40:I49)) | D15: шт. | E15: гр. I
B16: Бесплатные места в ложах | C16: =(SUM('Реализованные билеты'!J5:J38)+SUM('Реализованные билеты'!J40:J49)) | D16: шт. | E16: гр. J
B18: Всего бесплатных билетов (без абонементов) | C18: =((SUM('Реализованные билеты'!D5:D38)+SUM('Реализованные билеты'!D40:D49))+(SUM('Реализованные билеты'!H5:H38)+SUM('Реализованные билеты'!H40:H49))+(SUM('Реализованные билеты'!J5:J38)+SUM('Реализованные билеты'!J40:J49))) | D18: шт.
B19: Доля бесплатных билетов | C19: =IFERROR(((SUM('Реализованные билеты'!D5:D38)+SUM('Реализованные билеты'!D40:D49))+(SUM('Реализованные билеты'!H5:H38)+SUM('Реализованные билеты'!H40:H49))+(SUM('Реализованные билеты'!J5:J38)+SUM('Реализованные билеты'!J40:J49)))/((SUM('Реализованные билеты'!K5:K38)+SUM('Реализованные билеты'!K40:K49))-(SUM('Реализованные билеты'!E5:E38)+SUM('Реализованные билеты'!E40:E49))-(SUM('Реализованные билеты'!F5:F38)+SUM('Реализованные билеты'!F40:F49))),0) | D19: % | E19: бесплатные / (проходы − абонементы)
B21: Матчей регулярного чемпионата | C21: =COUNT('Реализованные билеты'!A5:A38) | D21: шт.
B22: Матчей плей-офф | C22: =COUNT('Реализованные билеты'!A40:A49) | D22: шт.
B23: Средняя посещаемость (регулярка) | C23: =IFERROR(SUM('Реализованные билеты'!K5:K38)/COUNT('Реализованные билеты'!A5:A38),0) | D23: зрит./матч
B24: Средняя посещаемость (плей-офф) | C24: =IFERROR(SUM('Реализованные билеты'!K40:K49)/COUNT('Реализованные билеты'!A40:A49),0) | D24: зрит./матч
B25: Средняя посещаемость (сезон) | C25: =IFERROR((SUM('Реализованные билеты'!K5:K38)+SUM('Реализованные билеты'!K40:K49))/(COUNT('Реализованные билеты'!A5:A38)+COUNT('Реализованные билеты'!A40:A49)),0) | D25: зрит./матч
B27: Вместимость арены | C27: =$H$2 | D27: мест | E27: изменяемый параметр в ячейке H2
B28: Суммарная посещаемость (регулярка) | C28: =SUM('Реализованные билеты'!K5:K38) | D28: зрит.
B29: Теоретическая ёмкость (регулярка) | C29: =$H$2*COUNT('Реализованные билеты'!A5:A38) | D29: мест
B30: Заполняемость арены (регулярка) | C30: =IFERROR((SUM('Реализованные билеты'!K5:K38)/COUNT('Реализованные билеты'!A5:A38))/$H$2,0) | D30: % | E30: средняя посещаемость / вместимость
B32: 2. Доход от реализации билетов, руб.
B33: Показатель | C33: Значение | D33: Ед. | E33: Формула / комментарий
B34: Доход — всего за сезон | C34: =(SUM('Доход от реализации билетов'!C4:C37)+SUM('Доход от реализации билетов'!C39:C48)) | D34: руб. | E34: гр. C
B35: регулярный чемпионат | C35: =SUM('Доход от реализации билетов'!C4:C37) | D35: руб.
B36: плей-офф | C36: =SUM('Доход от реализации билетов'!C39:C48) | D36: руб.
B37: Доход от платных билетов | C37: =(SUM('Доход от реализации билетов'!D4:D37)+SUM('Доход от реализации билетов'!D39:D48)) | D37: руб. | E37: гр. D
B38: Доход от абонементов/пакетов | C38: =(SUM('Доход от реализации билетов'!E4:E37)+SUM('Доход от реализации билетов'!E39:E48)) | D38: руб. | E38: гр. E
B39: Стоимость абонемента (за сезон) | C39: =IFERROR((SUM('Доход от реализации билетов'!E4:E37)+SUM('Доход от реализации билетов'!E39:E48))/MAX(MAX('Реализованные билеты'!E5:E38),MAX('Реализованные билеты'!E40:E49)),0) | D39: руб. | E39: доход абон. / число владельцев
B40: Доход от бизнес-клубов/ресторанов | C40: =(SUM('Доход от реализации билетов'!F4:F37)+SUM('Доход от реализации билетов'!F39:F48)) | D40: руб. | E40: гр. F
B41: Доход от лож | C41: =(SUM('Доход от реализации билетов'!G4:G37)+SUM('Доход от реализации билетов'!G39:G48)) | D41: руб. | E41: гр. G
B43: Средняя цена платного билета (регулярка) | C43: =IFERROR(SUM('Доход от реализации билетов'!D4:D37)/SUM('Реализованные билеты'!C5:C38),0) | D43: руб. | E43: доход платн. / платные билеты
B44: Средняя цена платного билета (сезон) | C44: =IFERROR((SUM('Доход от реализации билетов'!D4:D37)+SUM('Доход от реализации билетов'!D39:D48))/(SUM('Реализованные билеты'!C5:C38)+SUM('Реализованные билеты'!C40:C49)),0) | D44: руб.
B46: 3. Каналы продаж
...
