Workbook

Sheet FAQ по заполнению
A1: FAQ по заполнению вкладки «Реализованные билеты»
A2: 1. Какие данные нужно заполнять? По каждому матчу необходимо указать: • Дату игры • Количество реализованных платных и бесплатных билетов • Количество действующих платных и бесплатных абонементов/пакетов • Количество реализованных платных и бесплатных билетов в бизнес-клубах и ресторанах • Количество реализованных платных и бесплатных билетов в ложах - в случае реализации лож на весь сезон, сезонная стоимость ложи делится на количество матчей
A3: 2. Что входит в итоговую строку "Реализовано билетов, всего"? Общее количество всех реализованных билетов на соответствующий матч (сумма колонок C-J): • Платные и бесплатные билеты • Абонементы и пакеты • Билеты в бизнес-клубы и ложи
A4: 3. Что такое "бизнес-клубы и рестораны"? Это специальные места, которые обычно реализуются вместе с услугой кейтеринга (без учета лож). Если такие билеты не реализовываются, то укажите 0.
A5: 4. Что писать в колонке "Комментарий"? Любые необходимые пояснения по конкретному матчу (например, возможные ограничения по количеству зрителей, пояснения касательно билетной программы матча и т.п.).
A7: FAQ по заполнению вкладки «Доход от реализации билетов»
A8: 1. Какие данные нужно заполнять? По каждому матчу указываются: • Общая сумма дохода от реализации • Сумма дохода от реализации платных билетов • Сумма дохода от реализации абонементов/пакетов • Сумма дохода от реализации мест в бизнес-клубах и ресторанах (без учета стоимости кейтеринга) • Сумма дохода от реализации мест в ложах (без учета стоимости кейтеринга)
A9: 2. Что такое бизнес-клубы и рестораны? Это специальные зоны на арене с повышенным уровнем комфорта и доступом к кейтерингу. В отчёте указывается только доход от продажи мест, без учёта стоимости питания. Если такие билеты не реализовываются, то укажите 0.
A10: 3. Как указывать доход от абонементов/пакетов, лож, реализованных на весь сезон или его часть? Необходимо разделить общую сумму дохода от реализации на количество матчей и указать долю, приходящуюся на конкретный матч.
A11: 4. Учитывать ли стоимость кейтеринга в доходах от бизнес-клубов и лож? Нет. В отчёте указывается только стоимость мест, без учёта расходов на питание и обслуживание.
A12: 5. Что писать в комментариях? Любые пояснения
A14: FAQ по заполнению вкладки «Агенты и онлайн продажи»
... A19: 5. Что писать в комментариях? Любые пояснения

Sheet Реализованные билеты
A1: Поматчевая реализация
A2: № игры | B2: Дата | C2: Реализовано платных билетов на матч, шт. | D2: Реализовано бесплатных билетов на матч, шт. | E2: Действующие на матч платные абонементы/ пакеты, шт. | F2: Действующие на матч бесплатные абонементы/ пакеты, шт. | G2: Реализовано платных билетов в бизнес-клубы и рестораны на матч, шт. * | H2: Реализовано бесплатных билетов в бизнес-клубы и рестораны на матч, шт. * | I2: Реализоавано платных мест в ложах, шт. | J2: Реализоавано бесплатных мест в ложах, шт. | K2: Реализовано билетов на матч, всего, шт. | L2: Комментарий | M2: Посещаемость по протоколу
A4: РЕГУЛЯРНЫЙ ЧЕМПИОНАТ
A5: 1 | B5: 45922 | C5: 3498 | D5: 1912 | E5: 8501 | F5: 1129 | G5: - | H5: - | I5: 4 | J5: 42 | K5: =SUM(C5:J5) | M5: 0
A6: 2 | B6: 45924 | C6: 4818 | D6: 1525 | E6: 7244 | F6: 1127 | G6: - | H6: - | I6: 8 | J6: 364 | K6: =SUM(C6:J6) | M6: 0
A7: 3 | B7: 45926 | C7: 3596 | D7: 1618 | E7: 8505 | F7: 1137 | G7: - | H7: - | I7: 8 | J7: 222 | K7: =SUM(C7:J7) | M7: 0
A8: 4 | B8: 45929 | C8: 4776 | D8: 1750 | E8: 7244 | F8: 1131 | G8: - | H8: - | I8: 17 | J8: 168 | K8: =SUM(C8:J8) | M8: 0
A9: 5 | B9: 45931 | C9: 4780 | D9: 1688 | E9: 7244 | F9: 1131 | G9: - | H9: - | I9: 4 | J9: 239 | K9: =SUM(C9:J9) | M9: 0
A10: 6 | B10: 45936 | C10: 4651 | D10: 1753 | E10: 7244 | F10: 1131 | G10: - | H10: - | I10: 37 | J10: 270 | K10: =SUM(C10:J10) | M10: 0
A11: 7 | B11: 45944 | C11: 4750 | D11: 1759 | E11: 7244 | F11: 1137 | G11: - | H11: - | I11: 37 | J11: 159 | K11: =SUM(C11:J11) | M11: 0
A12: 8 | B12: 45947 | C12: 3572 | D12: 1814 | E12: 8505 | F12: 1131 | G12: - | H12: - | I12: 37 | J12: 27 | K12: =SUM(C12:J12) | M12: 0
A13: 9 | B13: 45954 | C13: 3150 | D13: 1775 | E13: 8921 | F13: 1143 | G13: - | H13: - | I13: 8 | J13: 89 | K13: =SUM(C13:J13) | M13: 0
A14: 10 | B14: 45958 | C14: 4604 | D14: 1676 | E14: 7522 | F14: 1136 | G14: - | H14: - | I14: 9 | J14: 139 | K14: =SUM(C14:J14) | M14: 0
A15: 11 | B15: 45960 | C15: 4592 | D15: 1721 | E15: 7522 | F15: 1136 | G15: - | H15: - | I15: 39 | J15: 76 | K15: =SUM(C15:J15) | M15: 0
A16: 12 | B16: 45964 | C16: 4294 | D16: 2055 | E16: 7522 | F16: 1136 | G16: - | H16: - | I16: 25 | J16: 54 | K16: =SUM(C16:J16) | M16: 0
... A29: 25 | B29: 46048 | C29: 3679 | D29: 1939 | E29: 7944 | F29: 1136 | G29: - | H29: - | I29: 59 | J29: 329 | K29: =SUM(C29:J29) | M29: 0
A30: 26 | B30: 03.02.2026 | C30: 2867 | D30: 1970 | E30: 8915 | F30: 1136 | G30: - | H30: - | I30: 26 | J30: 172 | K30: =SUM(C30:J30) | M30: 0
A31: 27 | B31: 10.02.2026 | C31: 2809 | D31: 1957 | E31: 8915 | F31: 1136 | G31: - | H31: - | I31: 6 | J31: 263 | K31: =SUM(C31:J31) | M31: 0
A32: 28 | B32: 46065 | C32: 2786 | D32: 2115 | E32: 8915 | F32: 1136 | G32: - | H32: - | I32: 40 | J32: 94 | K32: =SUM(C32:J32) | M32: 0
A33: 29 | B33: 46071 | C33: 2737 | D33: 2135 | E33: 8915 | F33: 1136 | G33: - | H33: - | I33: 34 | J33: 129 | K33: =SUM(C33:J33) | M33: 0
A34: 30 | B34: 46084 | C34: 2747 | D34: 2134 | E34: 8919 | F34: 1136 | G34: - | H34: - | I34: 10 | J34: 140 | K34: =SUM(C34:J34) | M34: 0
A35: 31 | B35: 46086 | C35: 2706 | D35: 2222 | E35: 8919 | F35: 1136 | G35: - | H35: - | I35: 47 | J35: 56 | K35: =SUM(C35:J35) | M35: 0
A36: 32 | B36: 46096 | C36: 1151 | D36: 1930 | E36: 10790 | F36: 1143 | G36: - | H36: - | I36: 21 | J36: 51 | K36: =SUM(C36:J36) | M36: 0
A37: 33 | B37: 46098 | C37: 2666 | D37: 2119 | E37: 8919 | F37: 1136 | G37: - | H37: - | I37: 17 | J37: 229 | K37: =SUM(C37:J37) | M37: 0
A38: 34 | B38: 46101 | C38: 1194 | D38: 1937 | E38: 10790 | F38: 1143 | G38: - | H38: - | I38: 12 | J38: 10 | K38: =SUM(C38:J38) | M38: 0
A39: ПЛЕЙ-ОФФ
B40: 46105 | C40: 4865 | D40: 1882 | E40: 6817 | F40: 1136 | G40: - | H40: - | I40: 9 | J40: 377 | K40: =SUM(C40:J40)
B41: 46107 | C41: 4802 | D41: 2006 | E41: 6817 | F41: 1136 | G41: - | H41: - | I41: 12 | J41: 313 | K41: =SUM(C41:J41)
B42: 46121 | C42: 4130 | D42: 2022 | E42: 7728 | F42: 1136 | G42: - | H42: - | I42: 38 | J42: 32 | K42: =SUM(C42:J42)
B43: 46123 | C43: 4269 | D43: 1870 | E43: 7728 | F43: 1136 | G43: - | H43: - | I43: 43 | J43: 40 | K43: =SUM(C43:J43)
A48: * Места, в стоимость которых включен кейтеринг

Sheet Доход от реализации билетов
A1: Поматчевая реализация
A2: № игры | B2: Дата | C2: Сумма дохода от всех реализованных билетов на матч | D2: Сумма дохода от реализованных платных билетов на матч | E2: Сумма дохода от реализованных на матч платных абонементов/ пакетов, шт. * | F2: Общая сумма дохода от реализованных платных билетов в бизнес-клубы и рестораны** на матч, шт. | G2: Общая сумма дохода от реализованных платных мест в ложах *** | H2: Комментарий
A3: РЕГУЛЯРНЫЙ ЧЕМПИОНАТ
A4: 1 | B4: 45922 | C4: 317062.96 | D4: 207879 | E4: 106583.96 | F4: - | G4: 2600
A5: 2 | B5: 45924 | C5: 228843.08 | D5: 141363 | E5: 82280.08 | F5: - | G5: 5200
A6: 3 | B6: 45926 | C6: 257080.96 | D6: 145297 | E6: 106583.96 | F6: - | G6: 5200
A7: 4 | B7: 45929 | C7: 241134.08 | D7: 147804 | E7: 82280.08 | F7: - | G7: 11050
A8: 5 | B8: 45931 | C8: 222116.08 | D8: 137236 | E8: 82280.08 | F8: - | G8: 2600
A9: 6 | B9: 45936 | C9: 251898.08 | D9: 155868 | E9: 82280.08 | F9: - | G9: 13750
A10: 7 | B10: 45944 | C10: 245273.08 | D10: 149243 | E10: 82280.08 | F10: - | G10: 13750
A11: 8 | B11: 45947 | C11: 267997.96 | D11: 147664 | E11: 106583.96 | F11: - | G11: 13750
A12: 9 | B12: 45954 | C12: 249109.91 | D12: 128998 | E12: 114911.91 | F12: - | G12: 5200
A13: 10 | B13: 45958 | C13: 224935.23 | D13: 131811 | E13: 87274.23 | F13: - | G13: 5850
A14: 11 | B14: 45960 | C14: 243661.23 | D14: 141337 | E14: 87274.23 | F14: - | G14: 15050
A15: 12 | B15: 45964 | C15: 235630.23 | D15: 132106 | E15: 87274.23 | F15: - | G15: 16250
... A37: 34 | B37: 46101 | C37: 265609.7 | D37: 89863 | E37: 167946.7 | F37: - | G37: 7800
A38: ПЛЕЙ-ОФФ
B39: 46105 | C39: 927613 | D39: 919090 | E39: - | F39: - | G39: 8523
B40: 46107 | C40: 941910 | D40: 930546 | E40: - | F40: - | G40: 11364
B41: 09.04.0206 | C41: 1155421.5 | D41: 1119435.5 | E41: - | F41: - | G41: 35986
B42: 46123 | C42: 1216273 | D42: 1139615 | E42: - | F42: - | G42: 76658 | H42: 35937 из лож - это ложа д8 для ак барс, может тогда в графе "реализованные билеты в ложу количество бьольше сделать?)
A48: * Если абонементы продавались на сезон или несколько матчей, то необходимо разделить полученный доход на количество игр и указать результат в поматчевой разбивке
A49: ** Места, в стоимость которых включен кейтеринг. Указывается только стоимость места без стоимости кейтеринга
A50: *** Если ложи реализовывались на весь сезон или несколько матчей, то необходимо разделить полученный доход на количество игр и указать результат в поматчевой разбивке. Указывается только стоимость мест в ложе без стооимсти кейтеринга

Sheet Агенты и онлайн продажи
A1: Реализация билетов через агентов *
A2: Название агента | B2: Реализовано билетов на матчи, всего, шт. | C2: Доход клуба от реализации платных билетов на матч, руб. | D2: Размер агентской комиссии, %
A8: Реализация билетов через каналы продаж *
A9: Канал продаж | B9: Реализовано билетов на матчи, всего, шт. | C9: Доход от реализации платных билетов на матч, руб.
A10: Онлайн
A11: Оффлайн
A12: Через агентов онлайн
A13: Через агентов оффлайн
A15: * Необходимо указать данные за весь сезон (включая плей-офф)

Sheet Расчеты
B1: Расчёт метрик билетной программы — сезон 2025/2026
G2: Вместимость арены, чел.: | H2: 15086
B3: 1. Реализация билетов, шт. | G3: Курс BYN→RUB (на 01.07.2025): | H3: 27
B4: Показатель | C4: Значение | D4: Ед. | E4: Формула / комментарий
B5: Посещаемость за сезон (всего проходов) | C5: =(SUM('Реализованные билеты'!K5:K38)+0) | D5: чел. | E5: гр. K — сумма разовых, абонементов, лож
B6: регулярный чемпионат | C6: =SUM('Реализованные билеты'!K5:K38) | D6: чел.
B7: плей-офф | C7: =0 | D7: чел.
B8: Платные билеты на матч (разовые) | C8: =(SUM('Реализованные билеты'!C5:C38)+0) | D8: шт. | E8: гр. C
B9: Бесплатные билеты на матч (разовые) | C9: =(SUM('Реализованные билеты'!D5:D38)+0) | D9: шт. | E9: гр. D
B10: Платных абонементов/пакетов (продано) | C10: =MAX(MAX('Реализованные билеты'!E5:E38),0) | D10: шт. | E10: MAX действующих, гр. E
B11: Бесплатных абонементов/пакетов (продано) | C11: =MAX(MAX('Реализованные билеты'!F5:F38),0) | D11: шт. | E11: MAX по гр. F
B12: абонемент-посещения за сезон (справочно) | C12: =(SUM('Реализованные билеты'!E5:E38)+0)+(SUM('Реализованные билеты'!F5:F38)+0) | D12: чел.
B13: Платные билеты в бизнес-клубы/рестораны | C13: =(SUM('Реализованные билеты'!G5:G38)+0) | D13: шт. | E13: гр. G
B14: Бесплатные билеты в бизнес-клубы/рестораны | C14: =(SUM('Реализованные билеты'!H5:H38)+0) | D14: шт. | E14: гр. H
B15: Платные места в ложах | C15: =(SUM('Реализованные билеты'!I5:I38)+0) | D15: шт. | E15: гр. I
B16: Бесплатные места в ложах | C16: =(SUM('Реализованные билеты'!J5:J38)+0) | D16: шт. | E16: гр. J
B17: Посещаемость по протоколу (за сезон) | C17: =(SUM('Реализованные билеты'!M5:M38)+0) | D17: чел. | E17: гр. M — из официального протокола матча
B18: Всего бесплатных билетов (без абонементов) | C18: =((SUM('Реализованные билеты'!D5:D38)+0)+(SUM('Реализованные билеты'!H5:H38)+0)+(SUM('Реализованные билеты'!J5:J38)+0)) | D18: шт.
B19: Доля бесплатных билетов | C19: =IFERROR(((SUM('Реализованные билеты'!D5:D38)+0)+(SUM('Реализованные билеты'!H5:H38)+0)+(SUM('Реализованные билеты'!J5:J38)+0))/((SUM('Реализованные билеты'!K5:K38)+0)-(SUM('Реализованные билеты'!E5:E38)+0)-(SUM('Реализованные билеты'!F5:F38)+0)),0) | D19: % | E19: бесплатные / (проходы − абонементы)
B20: Расхождение: факт − заявлено (билеты) | C20: =((SUM('Реализованные билеты'!M5:M38)+0)-(SUM('Реализованные билеты'!K5:K38)+0)) | D20: чел. | E20: посещаемость по протоколу − всего реализовано билетов
B21: Матчей регулярного чемпионата | C21: =COUNT('Реализованные билеты'!A5:A38) | D21: шт.
B22: Матчей плей-офф | C22: =0 | D22: шт.
B23: Средняя посещаемость (регулярка) | C23: =IFERROR(SUM('Реализованные билеты'!K5:K38)/COUNT('Реализованные билеты'!A5:A38),0) | D23: зрит./матч
B24: Средняя посещаемость (плей-офф) | C24: =IFERROR(0/0,0) | D24: зрит./матч
B25: Средняя посещаемость (сезон) | C25: =IFERROR((SUM('Реализованные билеты'!K5:K38)+0)/(COUNT('Реализованные билеты'!A5:A38)+0),0) | D25: зрит./матч
B26: Расхождение факта с заявленным, % | C26: =IFERROR(((SUM('Реализованные билеты'!M5:M38)+0)-(SUM('Реализованные билеты'!K5:K38)+0))/(SUM('Реализованные билеты'!K5:K38)+0),0) | D26: % | E26: (протокол − всего билетов) / всего билетов
B27: Вместимость арены | C27: =$H$2 | D27: мест | E27: изменяемый параметр в ячейке H2
B28: Суммарная посещаемость (регулярка) | C28: =SUM('Реализованные билеты'!K5:K38) | D28: зрит.
B29: Теоретическая ёмкость (регулярка) | C29: =$H$2*COUNT('Реализованные билеты'!A5:A38) | D29: мест
B30: Заполняемость арены (регулярка) | C30: =IFERROR((SUM('Реализованные билеты'!K5:K38)/COUNT('Реализованные билеты'!A5:A38))/$H$2,0) | D30: % | E30: средняя посещаемость / вместимость
B32: 2. Доход от реализации билетов, руб. РФ (пересчёт по курсу H3)
B33: Показатель | C33: Значение | D33: Ед. | E33: Формула / комментарий
B34: Доход — всего за сезон | C34: =((SUM('Доход от реализации билетов'!C4:C37)+0))*$H$3 | D34: руб. РФ | E34: гр. C (пересчёт по курсу H3)
B35: регулярный чемпионат | C35: =(SUM('Доход от реализации билетов'!C4:C37))*$H$3 | D35: руб. РФ
B36: плей-офф | C36: =(0)*$H$3 | D36: руб. РФ
B37: Доход от платных билетов | C37: =((SUM('Доход от реализации билетов'!D4:D37)+0))*$H$3 | D37: руб. РФ | E37: гр. D (пересчёт по курсу H3)
B38: Доход от абонементов/пакетов | C38: =((SUM('Доход от реализации билетов'!E4:E37)+0))*$H$3 | D38: руб. РФ | E38: гр. E (пересчёт по курсу H3)
B39: Стоимость абонемента (за сезон) | C39: =(IFERROR((SUM('Доход от реализации билетов'!E4:E37)+0)/MAX(MAX('Реализованные билеты'!E5:E38),0),0))*$H$3 | D39: руб. РФ | E39: доход абон. / число владельцев (пересчёт по курсу H3)
B40: Доход от бизнес-клубов/ресторанов | C40: =((SUM('Доход от реализации билетов'!F4:F37)+0))*$H$3 | D40: руб. РФ | E40: гр. F (пересчёт по курсу H3)
B41: Доход от лож | C41: =((SUM('Доход от реализации билетов'!G4:G37)+0))*$H$3 | D41: руб. РФ | E41: гр. G (пересчёт по курсу H3)
...
